Workbook

Sheet consolidated
A1: suburb | B1: density | C1: property | D1: price | E1: rooms | F1: bedroom | G1: toilets | H1: ensuite | I1: condition | J1: constituency | K1: council | L1: carport | M1: pool | N1: furnished | O1: cottage | P1: power | Q1: pbackup | R1: water | S1: wbackup | T1: gated | U1: garden
A2: ARCADIA | B2: =VLOOKUP(A:A,suburb!A:D,4,FALSE) -> MEDIUM | C2: HOUSE | D2: 750 | E2: 8 | F2: 4 | G2: 3 | H2: 2 | I2: 3 | J2: =VLOOKUP(A2,suburb!A:F,2,FALSE) -> SUNNINGDALE | K2: =VLOOKUP(A2,suburb!A:F,3,FALSE) -> HARARE MUNICIPALITY | L2: 2 | M2: 0 | N2: 1 | O2: 2 | P2: 1 | Q2: 0 | R2: 1 | S2: 1 | T2: 0 | U2: 1
A3: HATFIELD | B3: =VLOOKUP(A:A,suburb!A:D,4,FALSE) -> MEDIUM | C3: HOUSE | D3: 700 | E3: 8 | F3: 4 | G3: 4 | H3: 3 | I3: 3 | J3: =VLOOKUP(A3,suburb!A:F,2,FALSE) -> HATFIELD | K3: =VLOOKUP(A3,suburb!A:F,3,FALSE) -> HARARE MUNICIPALITY | L3: 2 | M3: 0 | N3: 1 | O3: 0 | P3: 1 | Q3: 0 | R3: 1 | S3: 1 | T3: 1 | U3: 1
A4: GOODHOPE | B4: =VLOOKUP(A:A,suburb!A:D,4,FALSE) -> MEDIUM | C4: HOUSE | D4: 750 | E4: 7 | F4: 2 | G4: 2 | H4: 1 | I4: 4 | J4: =VLOOKUP(A4,suburb!A:F,2,FALSE) -> HARARE WEST | K4: =VLOOKUP(A4,suburb!A:F,3,FALSE) -> HARARE MUNICIPALITY | L4: 2 | M4: 0 | N4: 0 | O4: 0 | P4: 1 | Q4: 0 | R4: 1 | S4: 0 | T4: 0 | U4: 1
A5: CHIKURUBI | B5: =VLOOKUP(A:A,suburb!A:D,4,FALSE) -> MEDIUM | C5: HOUSE | D5: 600 | E5: 7 | F5: 3 | G5: 1 | H5: 0 | I5: 3 | J5: =VLOOKUP(A5,suburb!A:F,2,FALSE) -> HARARE EAST | K5: =VLOOKUP(A5,suburb!A:F,3,FALSE) -> HARARE MUNICIPALITY | L5: 0 | M5: 0 | N5: 1 | O5: 0 | P5: 1 | Q5: 0 | R5: 1 | S5: 1 | T5: 0 | U5: 1
A6: CHADCOMBE | B6: =VLOOKUP(A:A,suburb!A:D,4,FALSE) -> MEDIUM | C6: HOUSE | D6: 650 | E6: 6 | F6: 3 | G6: 2 | H6: 1 | I6: 4 | J6: =VLOOKUP(A6,suburb!A:F,2,FALSE) -> HATFIELD | K6: =VLOOKUP(A6,suburb!A:F,3,FALSE) -> HARARE MUNICIPALITY | L6: 1 | M6: 0 | N6: 1 | O6: 3 | P6: 0 | Q6: 0 | R6: 1 | S6: 0 | T6: 0 | U6: 1
A7: HATFIELD | B7: =VLOOKUP(A:A,suburb!A:D,4,FALSE) -> MEDIUM | C7: HOUSE | D7: 650 | E7: 6 | F7: 3 | G7: 2 | H7: 1 | I7: 4 | J7: =VLOOKUP(A7,suburb!A:F,2,FALSE) -> HATFIELD | K7: =VLOOKUP(A7,suburb!A:F,3,FALSE) -> HARARE MUNICIPALITY | L7: 2 | M7: 0 | N7: 0 | O7: 0 | P7: 1 | Q7: 1 | R7: 1 | S7: 1 | T7: 0 | U7: 1
A8: PARKTOWN | B8: =VLOOKUP(A:A,suburb!A:D,4,FALSE) -> MEDIUM | C8: HOUSE | D8: 700 | E8: 6 | F8: 4 | G8: 2 | H8: 1 | I8: 4 | J8: =VLOOKUP(A8,suburb!A:F,2,FALSE) -> HATFIELD | K8: =VLOOKUP(A8,suburb!A:F,3,FALSE) -> HARARE MUNICIPALITY | L8: 2 | M8: 0 | N8: 1 | O8: 2 | P8: 1 | Q8: 1 | R8: 1 | S8: 1 | T8: 0 | U8: 1
A9: WARREN PARK | B9: =VLOOKUP(A:A,suburb!A:D,4,FALSE) -> HIGH | C9: HOUSE | D9: 550 | E9: 6 | F9: 3 | G9: 2 | H9: 1 | I9: 4 | J9: =VLOOKUP(A9,suburb!A:F,2,FALSE) -> HARARE CENTRAL | K9: =VLOOKUP(A9,suburb!A:F,3,FALSE) -> HARARE MUNICIPALITY | L9: 0 | M9: 0 | N9: 0 | O9: 0 | P9: 1 | Q9: 0 | R9: 1 | S9: 1 | T9: 0 | U9: 0
A10: UNIT B | B10: =VLOOKUP(A:A,suburb!A:D,4,FALSE) -> HIGH | C10: HOUSE | D10: 400 | E10: 7 | F10: 4 | G10: 2 | H10: 1 | I10: 3 | J10: =VLOOKUP(A10,suburb!A:F,2,FALSE) -> ZENGEZA EAST | K10: =VLOOKUP(A10,suburb!A:F,3,FALSE) -> CHITUNGWIZA MUNICIPALITY | L10: 0 | M10: 0 | N10: 1 | O10: 0 | P10: 1 | Q10: 0 | R10: 1 | S10: 0 | T10: 0 | U10: 0
A11: RIVERSIDE | B11: =VLOOKUP(A:A,suburb!A:D,4,FALSE) -> HIGH | C11: HOUSE | D11: 400 | E11: 7 | F11: 3 | G11: 2 | H11: 1 | I11: 3 | J11: =VLOOKUP(A11,suburb!A:F,2,FALSE) -> CHITUNGWIZA NORTH | K11: =VLOOKUP(A11,suburb!A:F,3,FALSE) -> CHITUNGWIZA MUNICIPALITY | L11: 1 | M11: 0 | N11: 1 | O11: 0 | P11: 1 | Q11: 0 | R11: 1 | S11: 0 | T11: 1 | U11: 0
A12: ARDBENNIE | B12: =VLOOKUP(A:A,suburb!A:D,4,FALSE) -> HIGH | C12: HOUSE | D12: 450 | E12: 7 | F12: 3 | G12: 2 | H12: 1 | I12: 3 | J12: =VLOOKUP(A12,suburb!A:F,2,FALSE) -> MBARE | K12: =VLOOKUP(A12,suburb!A:F,3,FALSE) -> HARARE MUNICIPALITY | L12: 0 | M12: 0 | N12: 0 | O12: 0 | P12: 1 | Q12: 1 | R12: 1 | S12: 0 | T12: 0 | U12: 0
A13: ADELAIDE PARK | B13: =VLOOKUP(A:A,suburb!A:D,4,FALSE) -> HIGH | C13: HOUSE | D13: 400 | E13: 7 | F13: 3 | G13: 2 | H13: 1 | I13: 3 | J13: =VLOOKUP(A13,suburb!A:F,2,FALSE) -> EPWORTH SOUTH | K13: =VLOOKUP(A13,suburb!A:F,3,FALSE) -> EPWORTH LOCAL BOARD | L13: 0 | M13: 0 | N13: 1 | O13: 0 | P13: 1 | Q13: 1 | R13: 1 | S13: 1 | T13: 0 | U13: 0
... A536: OVERSPILL | B536: =VLOOKUP(A:A,suburb!A:D,4,FALSE) -> COMPOUND | C536: CLUSTER | D536: 30 | E536: 1 | F536: 0 | G536: 1 | H536: 0 | I536: 2 | J536: =VLOOKUP(A536,suburb!A:F,2,FALSE) -> EPWORTH SOUTH | K536: =VLOOKUP(A536,suburb!A:F,3,FALSE) -> EPWORTH LOCAL BOARD | L536: 0 | M536: 0 | N536: 0 | O536: 0 | P536: 0 | Q536: 0 | R536: 0 | S536: 1 | T536: 0 | U536: 0
A537: CHADCOMBE | B537: MEDIUM | C537: HOUSE | D537: 750 | E537: 6 | F537: 3 | G537: 1 | H537: 0 | I537: 4 | J537: HATFIELD | K537: HARARE MUNICIPALITY | L537: 2 | M537: 0 | N537: 1 | O537: 1 | P537: 1 | Q537: 0 | R537: 1 | S537: 1 | T537: 0 | U537: 1
A538: CHADCOMBE | B538: MEDIUM | C538: HOUSE | D538: 700 | E538: 9 | F538: 4 | G538: 4 | H538: 3 | I538: 3 | J538: HATFIELD | K538: HARARE MUNICIPALITY | L538: 2 | M538: 0 | N538: 1 | O538: 0 | P538: 1 | Q538: 0 | R538: 1 | S538: 1 | T538: 1 | U538: 0
A539: CHIKURUBI | B539: MEDIUM | C539: HOUSE | D539: 750 | E539: 7 | F539: 2 | G539: 2 | H539: 1 | I539: 4 | J539: HARARE EAST | K539: HARARE MUNICIPALITY | L539: 2 | M539: 0 | N539: 0 | O539: 0 | P539: 1 | Q539: 0 | R539: 1 | S539: 0 | T539: 0 | U539: 1
A540: CHIKURUBI | B540: MEDIUM | C540: HOUSE | D540: 600 | E540: 7 | F540: 3 | G540: 1 | H540: 0 | I540: 3 | J540: HARARE EAST | K540: HARARE MUNICIPALITY | L540: 0 | M540: 0 | N540: 1 | O540: 0 | P540: 1 | Q540: 0 | R540: 1 | S540: 1 | T540: 0 | U540: 1
A541: QUEENSDALE | B541: MEDIUM | C541: HOUSE | D541: 650 | E541: 6 | F541: 3 | G541: 2 | H541: 1 | I541: 4 | J541: SUNNINGDALE | K541: HARARE MUNICIPALITY | L541: 1 | M541: 0 | N541: 1 | O541: 3 | P541: 0 | Q541: 0 | R541: 1 | S541: 0 | T541: 0 | U541: 1
A542: NETTLETON | B542: MEDIUM | C542: HOUSE | D542: 650 | E542: 6 | F542: 3 | G542: 2 | H542: 1 | I542: 4 | J542: SUNNINGDALE | K542: HARARE MUNICIPALITY | L542: 2 | M542: 0 | N542: 0 | O542: 0 | P542: 1 | Q542: 1 | R542: 1 | S542: 1 | T542: 0 | U542: 1
A543: QUEENSDALE | B543: MEDIUM | C543: HOUSE | D543: 700 | E543: 6 | F543: 4 | G543: 2 | H543: 1 | I543: 4 | J543: SUNNINGDALE | K543: HARARE MUNICIPALITY | L543: 2 | M543: 0 | N543: 1 | O543: 2 | P543: 1 | Q543: 1 | R543: 1 | S543: 1 | T543: 0 | U543: 1
A544: QUEENSDALE | B544: MEDIUM | C544: HOUSE | D544: 650 | E544: 6 | F544: 3 | G544: 2 | H544: 1 | I544: 4 | J544: SUNNINGDALE | K544: HARARE MUNICIPALITY | L544: 1 | M544: 0 | N544: 1 | O544: 0 | P544: 1 | Q544: 0 | R544: 1 | S544: 1 | T544: 0 | U544: 1
A545: NETTLETON | B545: MEDIUM | C545: HOUSE | D545: 650 | E545: 6 | F545: 2 | G545: 2 | H545: 1 | I545: 4 | J545: SUNNINGDALE | K545: HARARE MUNICIPALITY | L545: 1 | M545: 0 | N545: 1 | O545: 0 | P545: 1 | Q545: 0 | R545: 1 | S545: 0 | T545: 0 | U545: 1
A546: CHIKURUBI | B546: MEDIUM | C546: HOUSE | D546: 550 | E546: 7 | F546: 4 | G546: 2 | H546: 1 | I546: 3 | J546: HARARE EAST | K546: HARARE MUNICIPALITY | L546: 0 | M546: 0 | N546: 1 | O546: 0 | P546: 1 | Q546: 0 | R546: 1 | S546: 1 | T546: 1 | U546: 0
A547: CHADCOMBE | B547: MEDIUM | C547: HOUSE | D547: 450 | E547: 6 | F547: 4 | G547: 2 | H547: 1 | I547: 3 | J547: HATFIELD | K547: HARARE MUNICIPALITY | L547: 0 | M547: 0 | N547: 1 | O547: 0 | P547: 1 | Q547: 0 | R547: 1 | S547: 1 | T547: 0 | U547: 0
A548: NETTLETON | B548: MEDIUM | C548: HOUSE | D548: 650 | E548: 6 | F548: 3 | G548: 2 | H548: 1 | I548: 4 | J548: SUNNINGDALE | K548: HARARE MUNICIPALITY | L548: 0 | M548: 0 | N548: 1 | O548: 0 | P548: 1 | Q548: 0 | R548: 1 | S548: 1 | T548: 0 | U548: 1
... A941: MARLBOROUGH | B941: LOW | C941: CLUSTER | D941: 400 | E941: 2 | F941: 0 | G941: 1 | H941: 0 | I941: 4 | J941: HARARE WEST | K941: HARARE MUNICIPALITY | L941: 0 | M941: 0 | N941: 1 | O941: 0 | P941: 1 | Q941: 0 | R941: 1 | S941: 1 | T941: 0 | U941: 1

Sheet suburb
A1: suburb | B1: constituency | C1: council | D1: density
A2: MANYAME PARK | B2: ST MARYS | C2: CHITUNGWIZA MUNICIPALITY | D2: HIGH
A3: ST MARYS | B3: ST MARYS | C3: CHITUNGWIZA MUNICIPALITY | D3: HIGH
A4: ZENGEZA 1 | B4: ST MARYS | C4: CHITUNGWIZA MUNICIPALITY | D4: HIGH
A5: ROCKVIEW | B5: ZENGEZA WEST | C5: CHITUNGWIZA MUNICIPALITY | D5: HIGH
A6: ZENGEZA 5 | B6: ZENGEZA WEST | C6: CHITUNGWIZA MUNICIPALITY | D6: HIGH
A7: UNIT N | B7: CHITUNGWIZA NORTH | C7: CHITUNGWIZA MUNICIPALITY | D7: HIGH
A8: UNIT G | B8: CHITUNGWIZA NORTH | C8: CHITUNGWIZA MUNICIPALITY | D8: HIGH
A9: UNIT O | B9: CHITUNGWIZA NORTH | C9: CHITUNGWIZA MUNICIPALITY | D9: HIGH
A10: UNIT P | B10: CHITUNGWIZA NORTH | C10: CHITUNGWIZA MUNICIPALITY | D10: HIGH
A11: UNIT M | B11: CHITUNGWIZA SOUTH | C11: CHITUNGWIZA MUNICIPALITY | D11: HIGH
A12: UNIT L | B12: CHITUNGWIZA SOUTH | C12: CHITUNGWIZA MUNICIPALITY | D12: HIGH
... A180: CROWHILL | B180: HARARE EAST | C180: HARARE MUNICIPALITY | D180: LOW

Sheet coordinates
A1: address | B1: authority | C1: latitude | D1: longitude
A2: 2678 CHIEDZA | B2: CHITUNGWIZA MUNICIPALITY | C2: -17.994332 | D2: 31.032412
A3: 2700 ST MARYS | B3: CHITUNGWIZA MUNICIPALITY | C3: -17.9945 | D3: 31.0308
A4: 2685 ST MARYS | B4: CHITUNGWIZA MUNICIPALITY | C4: -17.994321 | D4: 31.031625
A5: NULL | B5: CHITUNGWIZA MUNICIPALITY | C5: -17.994962 | D5: 31.030625
A6: 9518 ST MARYS | B6: CHITUNGWIZA MUNICIPALITY | C6: -17.996614 | D6: 31.028392
A7: 2758 ST MARYS | B7: CHITUNGWIZA MUNICIPALITY | C7: -17.994918 | D7: 31.031573
A8: 2676 231 JEKACHEKA ROAD | B8: CHITUNGWIZA MUNICIPALITY | C8: -17.994362 | D8: 31.032176
A9: 2678 73 CHIEDZA ROAD_x000D_ | B9: CHITUNGWIZA MUNICIPALITY | C9: -17.994385 | D9: 31.032099
A10: NULL | B10: CHITUNGWIZA MUNICIPALITY | C10: -17.994807 | D10: 31.031954
A11: 2713 ST MARYS | B11: CHITUNGWIZA MUNICIPALITY | C11: -17.994485 | D11: 31.030016
A12: 2783 ST MARYS | B12: CHITUNGWIZA MUNICIPALITY | C12: -17.99543 | D12: 31.030514
A13: 2823 DEVE STREET | B13: CHITUNGWIZA MUNICIPALITY | C13: -17.995958 | D13: 31.030344
... A82: 9522 ST MARYS | B82: CHITUNGWIZA MUNICIPALITY | C82: -17.996505 | D82: 31.028757
A83: 2982 | B83: CHITUNGWIZA MUNICIPALITY | C83: -17.995877 | D83: 31.028092
A84: 2972 ST MARYS ST MARYS | B84: CHITUNGWIZA MUNICIPALITY | C84: -17.996212 | D84: 31.028462
A85: 3021 ST MARYS | B85: CHITUNGWIZA MUNICIPALITY | C85: -17.995304 | D85: 31.028772
A86: 2974 ST MARYS | B86: CHITUNGWIZA MUNICIPALITY | C86: -17.996234 | D86: 31.028274
A87: 3010 ST MARYS | B87: CHITUNGWIZA MUNICIPALITY | C87: -17.995728 | D87: 31.028231
A88: 2973 ST MARYS | B88: CHITUNGWIZA MUNICIPALITY | C88: -17.996166 | D88: 31.028371
A89: 10011 | B89: CHITUNGWIZA MUNICIPALITY | C89: -17.995385 | D89: 31.028065
A90: 2980 ST MARYS | B90: CHITUNGWIZA MUNICIPALITY | C90: -17.995823 | D90: 31.02805
A91: 3045 ST MARYS | B91: CHITUNGWIZA MUNICIPALITY | C91: -17.994742 | D91: 31.029346
A92: 2690 ST MARYS | B92: CHITUNGWIZA MUNICIPALITY | C92: -17.994491 | D92: 31.031434
A93: 3043 ST MARYS | B93: CHITUNGWIZA MUNICIPALITY | C93: -17.994757 | D93: 31.029146
A94: 2732 ST MARYS | B94: CHITUNGWIZA MUNICIPALITY | C94: -17.995105 | D94: 31.030069
A95: 2698 ST MARYS | B95: CHITUNGWIZA MUNICIPALITY | C95: -17.994492 | D95: 31.030925
A96: 2782 ST MARYS | B96: CHITUNGWIZA MUNICIPALITY | C96: -17.995513 | D96: 31.030597
A97: 2861 ST MARYS | B97: CHITUNGWIZA MUNICIPALITY | C97: -17.996339 | D97: 31.030709
A98: 6829 ST MARYS | B98: CHITUNGWIZA MUNICIPALITY | C98: -17.994123 | D98: 31.030131
A99: 3032 ST MARYS | B99: CHITUNGWIZA MUNICIPALITY | C99: -17.995076 | D99: 31.02912
A100: 6826 ST MARYS | B100: CHITUNGWIZA MUNICIPALITY | C100: -17.99409 | D100: 31.030417
A101: 2720 ST MARYS | B101: CHITUNGWIZA MUNICIPALITY | C101: -17.994699 | D101: 31.02968
... A199: NULL | B199: CHITUNGWIZA MUNICIPALITY | C199: -17.994813 | D199: 31.03184
A200: 2646 | B200: CHITUNGWIZA MUNICIPALITY | C200: -17.996345 | D200: 31.032545
A201: 8196 ST MARYS | B201: CHITUNGWIZA MUNICIPALITY | C201: -17.997001 | D201: 31.031003
A202: 2638 ST MARYS | B202: CHITUNGWIZA MUNICIPALITY | C202: -17.99657 | D202: 31.032908
A203: 2669 ST MARYS | B203: CHITUNGWIZA MUNICIPALITY | C203: -17.996497 | D203: 31.033349
A204: NULL | B204: CHITUNGWIZA MUNICIPALITY | C204: -17.997011 | D204: 31.033497
A205: 2645 BANGO | B205: CHITUNGWIZA MUNICIPALITY | C205: -17.996562 | D205: 31.032517
...
